Workbook

Sheet Dashboard
B1: Dashboard
B2: Painel geral da gestação — só leitura, alimentado pelas outras abas.
B4: SEMANA GESTACIONAL | E4: TRIMESTRE | H4: DPP
B5: =ROUNDDOWN((TODAY()-('_Engine'!B14-280))/7,0)&"ª semana" | E5: =IF(ROUNDDOWN((TODAY()-('_Engine'!B14-280))/7,0)<=13,"1º trimestre",IF(ROUNDDOWN((TODAY()-('_Engine'!B14-280))/7,0)<=27,"2º trimestre","3º trimestre")) | H5: ='_Engine'!B14
B7: % ENXOVAL PRONTO | E7: RESTANTE DO ORÇAMENTO ENXOVAL | H7: CONFIRMADOS NO CHÁ | K7: % MALA PRONTA
B8: ='_Engine'!B2 | E8: =('_Engine'!B3-'_Engine'!B4) | H8: ='_Engine'!B6 | K8: ='_Engine'!B12
B10: PRÓXIMA CONSULTA | E10: ORÇAMENTO TOTAL | H10: GASTO TOTAL | K10: SALDO DISPONÍVEL
B11: ='_Engine'!B10 | E11: ='Finanças'!B5 | H11: ='Finanças'!F5 | K11: ='Finanças'!J5
B13: Gastos por categoria
B14: Categoria | C14: Gasto real
B15: ='Finanças'!A8 | C15: ='Finanças'!C8
B16: ='Finanças'!A9 | C16: ='Finanças'!C9
B17: ='Finanças'!A10 | C17: ='Finanças'!C10
B18: ='Finanças'!A11 | C18: ='Finanças'!C11
B19: ='Finanças'!A12 | C19: ='Finanças'!C12
B21: Resumo de pendências
B22: Área | C22: Pendências
B23: Enxoval — itens faltando | C23: ='_Engine'!B5
B24: Chá — tarefas pendentes | C24: ='_Engine'!B9
B25: Mala — itens faltando | C25: ='_Engine'!B13

Sheet Consultas & Exames
B1: Consultas & Exames
B2: Histórico e próximos agendamentos do pré-natal.
A4: PRÓXIMA CONSULTA | C4: CONSULTAS AGENDADAS | E4: GASTO REALIZADO
A5: =IFERROR(MINIFS(A8:A200,A8:A200,">="&TODAY(),E8:E200,"Agendado"),"-") | C5: =COUNTIF(E8:E200,"Agendado") | E5: =SUMIFS(D8:D200,E8:E200,"Realizado")
A7: Data | B7: Tipo | C7: Profissional / Local | D7: Custo | E7: Status | F7: Observações
A8: 46122 | B8: Consulta | C8: Dra. Ana Lima | D8: 250 | E8: Realizado | F8: Pré-natal mensal
A9: 46150 | B9: Exame | C9: Lab Vida — USG morfológico | D9: 380 | E9: Realizado
A10: 46178 | B10: Consulta | C10: Dra. Ana Lima | D10: 250 | E10: Realizado
A11: 46206 | B11: Consulta | C11: Dra. Ana Lima | D11: 250 | E11: Agendado
A12: 46223 | B12: Exame | C12: Lab Vida — glicemia | D12: 120 | E12: Agendado
A13: 46241 | B13: Consulta | C13: Dra. Ana Lima | D13: 250 | E13: Agendado
A14: 46269 | B14: Consulta | C14: Dra. Ana Lima | D14: 250 | E14: Agendado

Sheet Planejamento de Chá
B1: Planejamento de Chá
B2: Convidados, tarefas e custos do chá de bebê.
A4: CONFIRMADOS (CABEÇAS) | C4: CUSTO PREVISTO | E4: CUSTO REAL
A5: =SUMPRODUCT((B9:B16="Confirmado")*(1+C9:C16)) | C5: =SUM(C27:C34) | E5: =SUM(D27:D34)
B7: Convidados
A8: Nome | B8: Status RSVP | C8: Acompanhantes
A9: Mariana Souza | B9: Confirmado | C9: 1
A10: Carlos Eduardo | B10: Confirmado | C10: 0
A11: Fernanda Alves | B11: Talvez | C11: 0
A12: Patrícia Gomes | B12: Confirmado | C12: 2
A13: Roberto Dias | B13: Não vai | C13: 0
A14: Juliana Castro | B14: Confirmado | C14: 1
A15: Lucas Pereira | B15: Talvez | C15: 0
A16: Beatriz Nunes | B16: Confirmado | C16: 0
B18: Tarefas
A19: Tarefa | B19: Responsável | C19: Prazo | D19: Status
A20: Reservar espaço | B20: Marido | C20: 46213 | D20: Concluída
A21: Contratar buffet | B21: Mãe | C21: 46223 | D21: Em andamento
A22: Encomendar bolo | B22: Você | C22: 46235 | D22: Pendente
A23: Decoração | B23: Irmã | C23: 46239 | D23: Pendente
A24: Convites digitais | B24: Você | C24: 46198 | D24: Concluída
A25: Lembrancinhas | B25: Madrinha | C25: 46244 | D25: Pendente
B27: Custos
A28: Item | B28: Categoria | C28: Custo previsto | D28: Custo real | E28: Fornecedor
A29: Aluguel do espaço | B29: Local | C29: 600 | D29: 600 | E29: Espaço Jardim
A30: Buffet completo | B30: Comida | C30: 1200 | D30: 1100 | E30: Sabor & Cia
A31: Bolo temático | B31: Comida | C31: 280 | D31: 0 | E31: Doces da Vó
A32: Decoração | B32: Decoração | C32: 450 | D32: 0 | E32: Arte em Festa
A33: Lembrancinhas (30un) | B33: Presentes | C33: 300 | D33: 0 | E33: Mimos Kids
A34: Fotógrafo | B34: Serviços | C34: 500 | D34: 500 | E34: Click Estúdio
A35: Convites digitais | B35: Papelaria | C35: 0 | D35: 0 | E35: Canva
A36: Som e iluminação | B36: Serviços | C36: 350 | D36: 0 | E36: Festa Som

Sheet Enxoval Inteligente
B1: Enxoval Inteligente
B2: Acompanhe o que já foi comprado, o que falta e quanto ainda falta investir.
B4: % ENXOVAL COMPLETO | F4: ITENS COM SALDO PENDENTE | J4: VALOR RESTANTE ESTIMADO
B5: =IF(SUM(E8:E200)=0,0,(SUM(F8:F200)+SUM(G8:G200))/SUM(E8:E200)) | F5: =COUNTIF(H8:H200,">0") | J5: =SUM(K8:K200)
A7: Categoria | B7: Item | C7: Tamanho | D7: Prioridade | E7: Sugerida | F7: Comprada | G7: Recebida | H7: Saldo | I7: Status | J7: Custo unit. | K7: Custo restante | L7: Fornecedor | M7: Observações | N7: Progresso
B8: Roupas
A9: Roupas | B9: Body manga curta | C9: RN | D9: Essencial | E9: 8 | F9: 0 | G9: 0 | H9: =MAX(E9-F9-G9,0) | I9: =IF(H9=0,"✓ completo",IF((F9+G9)=0,"○ não iniciado","● faltam "&H9)) | J9: 18 | K9: =H9*J9 | N9: =IF(E9=0,0,MIN((F9+G9)/E9,1))
A10: Roupas | B10: Body manga longa | C10: RN | D10: Essencial | E10: 6 | F10: 0 | G10: 0 | H10: =MAX(E10-F10-G10,0) | I10: =IF(H10=0,"✓ completo",IF((F10+G10)=0,"○ não iniciado","● faltam "&H10)) | J10: 20 | K10: =H10*J10 | N10: =IF(E10=0,0,MIN((F10+G10)/E10,1))
A11: Roupas | B11: Macacão plush | C11: RN | D11: Essencial | E11: 4 | F11: 0 | G11: 0 | H11: =MAX(E11-F11-G11,0) | I11: =IF(H11=0,"✓ completo",IF((F11+G11)=0,"○ não iniciado","● faltam "&H11)) | J11: 35 | K11: =H11*J11 | N11: =IF(E11=0,0,MIN((F11+G11)/E11,1))
A12: Roupas | B12: Calça/legging | C12: P | D12: Desejável | E12: 5 | F12: 0 | G12: 0 | H12: =MAX(E12-F12-G12,0) | I12: =IF(H12=0,"✓ completo",IF((F12+G12)=0,"○ não iniciado","● faltam "&H12)) | J12: 22 | K12: =H12*J12 | N12: =IF(E12=0,0,MIN((F12+G12)/E12,1))
A13: Roupas | B13: Casaco/jaqueta | C13: RN | D13: Desejável | E13: 2 | F13: 0 | G13: 0 | H13: =MAX(E13-F13-G13,0) | I13: =IF(H13=0,"✓ completo",IF((F13+G13)=0,"○ não iniciado","● faltam "&H13)) | J13: 45 | K13: =H13*J13 | N13: =IF(E13=0,0,MIN((F13+G13)/E13,1))
A14: Roupas | B14: Meias | C14: RN | D14: Essencial | E14: 6 | F14: 0 | G14: 0 | H14: =MAX(E14-F14-G14,0) | I14: =IF(H14=0,"✓ completo",IF((F14+G14)=0,"○ não iniciado","● faltam "&H14)) | J14: 8 | K14: =H14*J14 | N14: =IF(E14=0,0,MIN((F14+G14)/E14,1))
A15: Roupas | B15: Luva e touca | C15: RN | D15: Desejável | E15: 2 | F15: 0 | G15: 0 | H15: =MAX(E15-F15-G15,0) | I15: =IF(H15=0,"✓ completo",IF((F15+G15)=0,"○ não iniciado","● faltam "&H15)) | J15: 15 | K15: =H15*J15 | N15: =IF(E15=0,0,MIN((F15+G15)/E15,1))
B16: Subtotal — Roupas | J16: =IF(SUMIF($A$8:$A$200,"Roupas",$E$8:$E$200)=0,0,(SUMIF($A$8:$A$200,"Roupas",$F$8:$F$200)+SUMIF($A$8:$A$200,"Roupas",$G$8:$G$200))/SUMIF($A$8:$A$200,"Roupas",$E$8:$E$200))
B17: Higiene e Banho
A18: Higiene e Banho | B18: Fralda descartável RN (pacote) | C18: RN | D18: Essencial | E18: 6 | F18: 0 | G18: 0 | H18: =MAX(E18-F18-G18,0) | I18: =IF(H18=0,"✓ completo",IF((F18+G18)=0,"○ não iniciado","● faltam "&H18)) | J18: 32 | K18: =H18*J18 | N18: =IF(E18=0,0,MIN((F18+G18)/E18,1))
A19: Higiene e Banho | B19: Fralda descartável P (pacote) | C19: P | D19: Essencial | E19: 4 | F19: 0 | G19: 0 | H19: =MAX(E19-F19-G19,0) | I19: =IF(H19=0,"✓ completo",IF((F19+G19)=0,"○ não iniciado","● faltam "&H19)) | J19: 34 | K19: =H19*J19 | N19: =IF(E19=0,0,MIN((F19+G19)/E19,1))
A20: Higiene e Banho | B20: Toalha com capuz | C20: Único | D20: Essencial | E20: 3 | F20: 0 | G20: 0 | H20: =MAX(E20-F20-G20,0) | I20: =IF(H20=0,"✓ completo",IF((F20+G20)=0,"○ não iniciado","● faltam "&H20)) | J20: 40 | K20: =H20*J20 | N20: =IF(E20=0,0,MIN((F20+G20)/E20,1))
A21: Higiene e Banho | B21: Kit higiene (escova, tesoura etc.) | C21: Único | D21: Essencial | E21: 1 | F21: 0 | G21: 0 | H21: =MAX(E21-F21-G21,0) | I21: =IF(H21=0,"✓ completo",IF((F21+G21)=0,"○ não iniciado","● faltam "&H21)) | J21: 60 | K21: =H21*J21 | N21: =IF(E21=0,0,MIN((F21+G21)/E21,1))
A22: Higiene e Banho | B22: Banheira | C22: Único | D22: Desejável | E22: 1 | F22: 0 | G22: 0 | H22: =MAX(E22-F22-G22,0) | I22: =IF(H22=0,"✓ completo",IF((F22+G22)=0,"○ não iniciado","● faltam "&H22)) | J22: 120 | K22: =H22*J22 | N22: =IF(E22=0,0,MIN((F22+G22)/E22,1))
A23: Higiene e Banho | B23: Sabonete e shampoo neutro | C23: Único | D23: Essencial | E23: 2 | F23: 0 | G23: 0 | H23: =MAX(E23-F23-G23,0) | I23: =IF(H23=0,"✓ completo",IF((F23+G23)=0,"○ não iniciado","● faltam "&H23)) | J23: 25 | K23: =H23*J23 | N23: =IF(E23=0,0,MIN((F23+G23)/E23,1))
B24: Subtotal — Higiene e Banho | J24: =IF(SUMIF($A$8:$A$200,"Higiene e Banho",$E$8:$E$200)=0,0,(SUMIF($A$8:$A$200,"Higiene e Banho",$F$8:$F$200)+SUMIF($A$8:$A$200,"Higiene e Banho",$G$8:$G$200))/SUMIF($A$8:$A$200,"Higiene e Banho",$E$8:$E$200))
B25: Quarto e Mobiliário
A26: Quarto e Mobiliário | B26: Berço | C26: Único | D26: Essencial | E26: 1 | F26: 0 | G26: 0 | H26: =MAX(E26-F26-G26,0) | I26: =IF(H26=0,"✓ completo",IF((F26+G26)=0,"○ não iniciado","● faltam "&H26)) | J26: 650 | K26: =H26*J26 | N26: =IF(E26=0,0,MIN((F26+G26)/E26,1))
A27: Quarto e Mobiliário | B27: Colchão de berço | C27: Único | D27: Essencial | E27: 1 | F27: 0 | G27: 0 | H27: =MAX(E27-F27-G27,0) | I27: =IF(H27=0,"✓ completo",IF((F27+G27)=0,"○ não iniciado","● faltam "&H27)) | J27: 180 | K27: =H27*J27 | N27: =IF(E27=0,0,MIN((F27+G27)/E27,1))
A28: Quarto e Mobiliário | B28: Jogo de lençol | C28: Único | D28: Essencial | E28: 3 | F28: 0 | G28: 0 | H28: =MAX(E28-F28-G28,0) | I28: =IF(H28=0,"✓ completo",IF((F28+G28)=0,"○ não iniciado","● faltam "&H28)) | J28: 70 | K28: =H28*J28 | N28: =IF(E28=0,0,MIN((F28+G28)/E28,1))
A29: Quarto e Mobiliário | B29: Cômoda/trocador | C29: Único | D29: Desejável | E29: 1 | F29: 0 | G29: 0 | H29: =MAX(E29-F29-G29,0) | I29: =IF(H29=0,"✓ completo",IF((F29+G29)=0,"○ não iniciado","● faltam "&H29)) | J29: 450 | K29: =H29*J29 | N29: =IF(E29=0,0,MIN((F29+G29)/E29,1))
A30: Quarto e Mobiliário | B30: Móbile/decoração | C30: Único | D30: Desejável | E30: 1 | F30: 0 | G30: 0 | H30: =MAX(E30-F30-G30,0) | I30: =IF(H30=0,"✓ completo",IF((F30+G30)=0,"○ não iniciado","● faltam "&H30)) | J30: 80 | K30: =H30*J30 | N30: =IF(E30=0,0,MIN((F30+G30)/E30,1))
B31: Subtotal — Quarto e Mobiliário | J31: =IF(SUMIF($A$8:$A$200,"Quarto e Mobiliário",$E$8:$E$200)=0,0,(SUMIF($A$8:$A$200,"Quarto e Mobiliário",$F$8:$F$200)+SUMIF($A$8:$A$200,"Quarto e Mobiliário",$G$8:$G$200))/SUMIF($A$8:$A$200,"Quarto e Mobiliário",$E$8:$E$200))
B32: Amamentação e Alimentação
A33: Amamentação e Alimentação | B33: Sutiã de amamentação | C33: Único | D33: Essencial | E33: 3 | F33: 0 | G33: 0 | H33: =MAX(E33-F33-G33,0) | I33: =IF(H33=0,"✓ completo",IF((F33+G33)=0,"○ não iniciado","● faltam "&H33)) | J33: 40 | K33: =H33*J33 | N33: =IF(E33=0,0,MIN((F33+G33)/E33,1))
A34: Amamentação e Alimentação | B34: Absorvente para seios | C34: Único | D34: Desejável | E34: 2 | F34: 0 | G34: 0 | H34: =MAX(E34-F34-G34,0) | I34: =IF(H34=0,"✓ completo",IF((F34+G34)=0,"○ não iniciado","● faltam "&H34)) | J34: 20 | K34: =H34*J34 | N34: =IF(E34=0,0,MIN((F34+G34)/E34,1))
A35: Amamentação e Alimentação | B35: Mamadeira | C35: Único | D35: Desejável | E35: 2 | F35: 0 | G35: 0 | H35: =MAX(E35-F35-G35,0) | I35: =IF(H35=0,"✓ completo",IF((F35+G35)=0,"○ não iniciado","● faltam "&H35)) | J35: 30 | K35: =H35*J35 | N35: =IF(E35=0,0,MIN((F35+G35)/E35,1))
A36: Amamentação e Alimentação | B36: Almofada de amamentação | C36: Único | D36: Desejável | E36: 1 | F36: 0 | G36: 0 | H36: =MAX(E36-F36-G36,0) | I36: =IF(H36=0,"✓ completo",IF((F36+G36)=0,"○ não iniciado","● faltam "&H36)) | J36: 90 | K36: =H36*J36 | N36: =IF(E36=0,0,MIN((F36+G36)/E36,1))
A37: Amamentação e Alimentação | B37: Esterilizador | C37: Único | D37: Desejável | E37: 1 | F37: 0 | G37: 0 | H37: =MAX(E37-F37-G37,0) | I37: =IF(H37=0,"✓ completo",IF((F37+G37)=0,"○ não iniciado","● faltam "&H37)) | J37: 150 | K37: =H37*J37 | N37: =IF(E37=0,0,MIN((F37+G37)/E37,1))
B38: Subtotal — Amamentação e Alimentação | J38: =IF(SUMIF($A$8:$A$200,"Amamentação e Alimentação",$E$8:$E$200)=0,0,(SUMIF($A$8:$A$200,"Amamentação e Alimentação",$F$8:$F$200)+SUMIF($A$8:$A$200,"Amamentação e Alimentação",$G$8:$G$200))/SUMIF($A$8:$A$200,"Amamentação e Alimentação",$E$8:$E$200))
B39: Passeio e Transporte
A40: Passeio e Transporte | B40: Bebê conforto | C40: Único | D40: Essencial | E40: 1 | F40: 0 | G40: 0 | H40: =MAX(E40-F40-G40,0) | I40: =IF(H40=0,"✓ completo",IF((F40+G40)=0,"○ não iniciado","● faltam "&H40)) | J40: 400 | K40: =H40*J40 | N40: =IF(E40=0,0,MIN((F40+G40)/E40,1))
A41: Passeio e Transporte | B41: Carrinho de bebê | C41: Único | D41: Essencial | E41: 1 | F41: 0 | G41: 0 | H41: =MAX(E41-F41-G41,0) | I41: =IF(H41=0,"✓ completo",IF((F41+G41)=0,"○ não iniciado","● faltam "&H41)) | J41: 800 | K41: =H41*J41 | N41: =IF(E41=0,0,MIN((F41+G41)/E41,1))
A42: Passeio e Transporte | B42: Bolsa maternidade | C42: Único | D42: Essencial | E42: 1 | F42: 0 | G42: 0 | H42: =MAX(E42-F42-G42,0) | I42: =IF(H42=0,"✓ completo",IF((F42+G42)=0,"○ não iniciado","● faltam "&H42)) | J42: 180 | K42: =H42*J42 | N42: =IF(E42=0,0,MIN((F42+G42)/E42,1))
...

Sheet Mala Maternidade
B1: Mala Maternidade
B2: Checklist do que precisa estar na mala até a 36ª semana.
A4: % MALA PRONTA
A5: =(COUNTIF(C9:C12,TRUE)+COUNTIF(C14:C18,TRUE)+COUNTIF(C20:C22,TRUE))/(COUNTA(B9:B12)+COUNTA(B14:B18)+COUNTA(B20:B22))
A7: Categoria | B7: Item | C7: Marcado | D7: Observações
B8: Mamãe
A9: Mamãe | B9: Roupa para internação | C9: FALSE
A10: Mamãe | B10: Roupa para alta | C10: FALSE
A11: Mamãe | B11: Produtos de higiene pessoal | C11: TRUE
A12: Mamãe | B12: Documentos pessoais e do plano | C12: TRUE
B13: Bebê
A14: Bebê | B14: Body e macacão para alta | C14: FALSE
A15: Bebê | B15: Manta | C15: TRUE
A16: Bebê | B16: Fraldas (reserva pequena) | C16: TRUE
A17: Bebê | B17: Touca e luvas | C17: FALSE
A18: Bebê | B18: Saída de maternidade | C18: FALSE
B19: Documentos
A20: Documentos | B20: RG e CPF | C20: TRUE
A21: Documentos | B21: Cartão do convênio | C21: TRUE
A22: Documentos | B22: Carteira de pré-natal | C22: TRUE

Sheet Finanças
B1: Finanças
B2: Orçamento total, gastos por categoria e fluxo de caixa.
B4: ORÇAMENTO TOTAL | F4: GASTO TOTAL | J4: SALDO DISPONÍVEL
B5: =SUM(B8:B12) | F5: =SUM(C8:C12) | J5: =SUM(D8:D12)
A7: Categoria | B7: Orçado | C7: Gasto real | D7: Saldo | E7: % usado
A8: Enxoval | B8: ='_Engine'!B3 | C8: ='_Engine'!B4 | D8: =B8-C8 | E8: =IF(B8=0,0,C8/B8)
A9: Chá de bebê | B9: ='_Engine'!B7 | C9: ='_Engine'!B8 | D9: =B9-C9 | E9: =IF(B9=0,0,C9/B9)
A10: Saúde e consultas | B10: 0 | C10: ='_Engine'!B11 | D10: =B10-C10 | E10: =IF(B10=0,0,C10/B10)
A11: Hospital e parto | B11: 0 | C11: 0 | D11: =B11-C11 | E11: =IF(B11=0,0,C11/B11)
A12: Reserva para imprevistos | B12: 0 | C12: 0 | D12: =B12-C12 | E12: =IF(B12=0,0,C12/B12)
B14: Fluxo de caixa mensal (previsto)
A15: Mês | B15: Entradas previstas | C15: Saídas previstas | D15: Saldo acumulado
A16: Jun/26 | B16: 1500 | C16: 1000 | D16: =B16-C16
A17: Jul/26 | B17: 1500 | C17: 1000 | D17: =D16+B17-C17
A18: Ago/26 | B18: 1500 | C18: 1000 | D18: =D17+B18-C18
A19: Set/26 | B19: 1500 | C19: 1000 | D19: =D18+B19-C19
A20: Out/26 | B20: 1500 | C20: 1000 | D20: =D19+B20-C20
A21: Nov/26 | B21: 1500 | C21: 1000 | D21: =D20+B21-C21

Sheet Planner & Decisões
B1: Planner & Decisões
B2: Datas importantes, nomes em consideração e fornecedores.
B4: Datas importantes
A5: Data prevista do parto (DPP) | C5: 46280
B7: Nomes em consideração
A8: Nome | B8: Significado | C8: Nota mamãe | D8: Nota papai | E8: Nota média
A9: Helena | B9: Luz, brilhante | C9: 5 | D9: 4 | E9: =AVERAGE(C9:D9)
A10: Valentina | B10: Forte, saudável | C10: 4 | D10: 4 | E10: =AVERAGE(C10:D10)
A11: Sophia | B11: Sabedoria | C11: 3 | D11: 5 | E11: =AVERAGE(C11:D11)
A12: Laura | B12: Coroa de louros | C12: 5 | D12: 3 | E12: =AVERAGE(C12:D12)
A13: Alice | B13: Nobre, verdadeira | C13: 4 | D13: 4 | E13: =AVERAGE(C13:D13)
B15: Fornecedores
A16: Categoria | B16: Fornecedor | C16: Contato | D16: Status
A17: Maternidade | B17: Hospital Vida Nova | C17: (67) 99999-1111 | D17: Contratado
A18: Fotógrafo newborn | B18: Click Estúdio | C18: (67) 99999-2222 | D18: Em negociação
A19: Doula | B19: Camila Ferreira | C19: (67) 99999-3333 | D19: Contratado
A20: Pediatra | B20: Dr. Felipe Rocha | C20: (67) 99999-4444 | D20: Contratado

Sheet _Engine
A1: Indicador | B1: Valor
A2: Enxoval_pctCompleto | B2: ='Enxoval Inteligente'!B5
A3: Enxoval_orcadoTotal | B3: =SUMPRODUCT('Enxoval Inteligente'!E8:E200,'Enxoval Inteligente'!J8:J200)
A4: Enxoval_gastoReal | B4: =SUMPRODUCT('Enxoval Inteligente'!F8:F200,'Enxoval Inteligente'!J8:J200)
A5: Enxoval_itensPendentes | B5: ='Enxoval Inteligente'!F5
A6: Cha_confirmados | B6: ='Planejamento de Chá'!A5
A7: Cha_orcadoTotal | B7: ='Planejamento de Chá'!C5
A8: Cha_gastoReal | B8: ='Planejamento de Chá'!E5
A9: Cha_tarefasPendentes | B9: =COUNTIF('Planejamento de Chá'!D20:D25,"Pendente")
A10: Consultas_proximaData | B10: ='Consultas & Exames'!A5
A11: Consultas_gastoReal | B11: ='Consultas & Exames'!E5
A12: Mala_pctCompleto | B12: ='Mala Maternidade'!A5
A13: Mala_itensPendentes | B13: =(COUNTA(B9:B12)+COUNTA(B14:B18)+COUNTA(B20:B22))-(COUNTIF(C9:C12,TRUE)+COUNTIF(C14:C18,TRUE)+COUNTIF(C20:C22,TRUE))
A14: DPP | B14: ='Planner & Decisões'!C5
